Traceback (most recent call last):
  File "/home/mark/miniconda3/envs/jupyterbook/lib/python3.11/site-packages/jupyter_cache/executors/utils.py", line 58, in single_nb_execution
    executenb(
  File "/home/mark/miniconda3/envs/jupyterbook/lib/python3.11/site-packages/nbclient/client.py", line 1305, in execute
    return NotebookClient(nb=nb, resources=resources, km=km, **kwargs).execute()
           ^^^^^^^^^^^^^^^^^^^^^^^^^^^^^^^^^^^^^^^^^^^^^^^^^^^^^^^^^^^^^^^^^^^^^
  File "/home/mark/miniconda3/envs/jupyterbook/lib/python3.11/site-packages/jupyter_core/utils/__init__.py", line 166, in wrapped
    return loop.run_until_complete(inner)
           ^^^^^^^^^^^^^^^^^^^^^^^^^^^^^^
  File "/home/mark/miniconda3/envs/jupyterbook/lib/python3.11/asyncio/base_events.py", line 653, in run_until_complete
    return future.result()
           ^^^^^^^^^^^^^^^
  File "/home/mark/miniconda3/envs/jupyterbook/lib/python3.11/site-packages/nbclient/client.py", line 705, in async_execute
    await self.async_execute_cell(
  File "/home/mark/miniconda3/envs/jupyterbook/lib/python3.11/site-packages/nbclient/client.py", line 1058, in async_execute_cell
    await self._check_raise_for_error(cell, cell_index, exec_reply)
  File "/home/mark/miniconda3/envs/jupyterbook/lib/python3.11/site-packages/nbclient/client.py", line 914, in _check_raise_for_error
    raise CellExecutionError.from_cell_and_msg(cell, exec_reply_content)
nbclient.exceptions.CellExecutionError: An error occurred while executing the following cell:
------------------

import pandas as pd
import csv
import matplotlib.patches as mpatches
import matplotlib.pyplot as plt
import plotly.express as px
import seaborn as sns
from plotly.subplots import make_subplots
from collections import defaultdict
import plotly.graph_objects as go

import statsmodels.api as sm


!pip install numpy
!pip install plotly
!pip install pandas
!pip install matplotlib
!pip install -U seaborn
!pip install seaborn
!pip install csv
!pip install statsmodels
------------------


[0;31m---------------------------------------------------------------------------[0m
[0;31mModuleNotFoundError[0m                       Traceback (most recent call last)
Cell [0;32mIn[1], line 11[0m
[1;32m      8[0m [38;5;28;01mfrom[39;00m [38;5;21;01mcollections[39;00m [38;5;28;01mimport[39;00m defaultdict
[1;32m      9[0m [38;5;28;01mimport[39;00m [38;5;21;01mplotly[39;00m[38;5;21;01m.[39;00m[38;5;21;01mgraph_objects[39;00m [38;5;28;01mas[39;00m [38;5;21;01mgo[39;00m
[0;32m---> 11[0m [38;5;28;01mimport[39;00m [38;5;21;01mstatsmodels[39;00m[38;5;21;01m.[39;00m[38;5;21;01mapi[39;00m [38;5;28;01mas[39;00m [38;5;21;01msm[39;00m
[1;32m     14[0m get_ipython()[38;5;241m.[39msystem([38;5;124m'[39m[38;5;124mpip install numpy[39m[38;5;124m'[39m)
[1;32m     15[0m get_ipython()[38;5;241m.[39msystem([38;5;124m'[39m[38;5;124mpip install plotly[39m[38;5;124m'[39m)

[0;31mModuleNotFoundError[0m: No module named 'statsmodels'

